{"name": "test_failing_exception", "status": "failed", "statusDetails": {"message": "AssertionError: ValueError not raised", "trace": "self = <test_example.TestExampleFailure testMethod=test_failing_exception>\n\n    def test_failing_exception(self):\n        \"\"\"Test d'exception qui échoue.\"\"\"\n>       with self.assertRaises(ValueError):\nE       AssertionError: ValueError not raised\n\nexamples\\test_example.py:42: AssertionError"}, "description": "Test d'exception qui échoue.", "start": 1744388815983, "stop": 1744388815984, "uuid": "5ed5bed4-bcdf-4b34-a927-b53ddf459aa3", "historyId": "bb1c97063a1ea262ec11dc18e6cba7e0", "testCaseId": "bb1c97063a1ea262ec11dc18e6cba7e0", "fullName": "examples.test_example.TestExampleFailure#test_failing_exception", "labels": [{"name": "parentSuite", "value": "examples"}, {"name": "suite", "value": "test_example"}, {"name": "subSuite", "value": "TestExampleFailure"}, {"name": "host", "value": "DESKTOP-ORG3GN0"}, {"name": "thread", "value": "2352-MainThread"}, {"name": "framework", "value": "pytest"}, {"name": "language", "value": "cpython3"}, {"name": "package", "value": "examples.test_example"}]}